[2023-08-22T07:29:49.593+0000] {taskinstance.py:1103} INFO - Dependencies all met for dep_context=non-requeueable deps ti=<TaskInstance: csv_dag.counting_rows scheduled__2023-08-17T00:00:00+00:00 [queued]>
[2023-08-22T07:29:49.605+0000] {taskinstance.py:1103} INFO - Dependencies all met for dep_context=requeueable deps ti=<TaskInstance: csv_dag.counting_rows scheduled__2023-08-17T00:00:00+00:00 [queued]>
[2023-08-22T07:29:49.606+0000] {taskinstance.py:1308} INFO - Starting attempt 1 of 2
[2023-08-22T07:29:49.629+0000] {taskinstance.py:1327} INFO - Executing <Task(PythonOperator): counting_rows> on 2023-08-17 00:00:00+00:00
[2023-08-22T07:29:49.635+0000] {standard_task_runner.py:57} INFO - Started process 40507 to run task
[2023-08-22T07:29:49.639+0000] {standard_task_runner.py:84} INFO - Running: ['***', 'tasks', 'run', 'csv_dag', 'counting_rows', 'scheduled__2023-08-17T00:00:00+00:00', '--job-id', '46', '--raw', '--subdir', 'DAGS_FOLDER/csv_dag.py', '--cfg-path', '/tmp/tmp66yxycj1']
[2023-08-22T07:29:49.641+0000] {standard_task_runner.py:85} INFO - Job 46: Subtask counting_rows
[2023-08-22T07:29:49.693+0000] {task_command.py:410} INFO - Running <TaskInstance: csv_dag.counting_rows scheduled__2023-08-17T00:00:00+00:00 [running]> on host 908f67153615
[2023-08-22T07:29:49.788+0000] {taskinstance.py:1547} INFO - Exporting env vars: AIRFLOW_CTX_DAG_EMAIL='***@my_first_dag.com' AIRFLOW_CTX_DAG_OWNER='***' AIRFLOW_CTX_DAG_ID='csv_dag' AIRFLOW_CTX_TASK_ID='counting_rows' AIRFLOW_CTX_EXECUTION_DATE='2023-08-17T00:00:00+00:00' AIRFLOW_CTX_TRY_NUMBER='1' AIRFLOW_CTX_DAG_RUN_ID='scheduled__2023-08-17T00:00:00+00:00'
[2023-08-22T07:29:49.790+0000] {taskinstance.py:1824} ERROR - Task failed with exception
Traceback (most recent call last):
  File "/home/airflow/.local/lib/python3.7/site-packages/airflow/operators/python.py", line 181, in execute
    return_value = self.execute_callable()
  File "/home/airflow/.local/lib/python3.7/site-packages/airflow/operators/python.py", line 198, in execute_callable
    return self.python_callable(*self.op_args, **self.op_kwargs)
TypeError: count_rows() missing 1 required positional argument: 'csv_data'
[2023-08-22T07:29:49.798+0000] {taskinstance.py:1350} INFO - Marking task as UP_FOR_RETRY. dag_id=csv_dag, task_id=counting_rows, execution_date=20230817T000000, start_date=20230822T072949, end_date=20230822T072949
[2023-08-22T07:29:49.812+0000] {standard_task_runner.py:109} ERROR - Failed to execute job 46 for task counting_rows (count_rows() missing 1 required positional argument: 'csv_data'; 40507)
[2023-08-22T07:29:49.851+0000] {local_task_job_runner.py:225} INFO - Task exited with return code 1
[2023-08-22T07:29:49.878+0000] {taskinstance.py:2653} INFO - 0 downstream tasks scheduled from follow-on schedule check
